<?xml version="1.0" encoding="UTF-8"?>
<!-- Generated by org.testng.reporters.JUnitXMLReporter -->
<testsuite hostname="ChetnaM-PC" ignored="0" name="suite20" tests="3" failures="2" timestamp="23 May 2017 15:57:21 GMT" time="1448.083" errors="0">
  <testcase name="verify" time="657.79" classname="com.adv.qa.selenium.tests.currency.A039_EnquiryTest"/>
  <testcase name="verify" time="626.806" classname="com.adv.qa.selenium.tests.currency.A040_ICA_Data_EntryTest">
    <failure type="java.lang.AssertionError" message="New group displayed not displayed in the grid expected [true] but found [false]">
      <![CDATA[java.lang.AssertionError: New group displayed not displayed in the grid expected [true] but found [false]
	at org.testng.Assert.fail(Assert.java:94)
	at org.testng.Assert.failNotEquals(Assert.java:513)
	at org.testng.Assert.assertTrue(Assert.java:42)
	at com.adv.qa.selenium.framework.Assert.assertTrue(Assert.java:43)
	at com.adv.qa.selenium.tests.currency.A040_ICA_Data_EntryTest.verifyGroup(A040_ICA_Data_EntryTest.java:165)
	at com.adv.qa.selenium.tests.currency.A040_ICA_Data_EntryTest.accountDetailEnquiry(A040_ICA_Data_EntryTest.java:119)
	at com.adv.qa.selenium.tests.currency.A040_ICA_Data_EntryTest.verify(A040_ICA_Data_EntryTest.java:62)
	at sun.reflect.NativeMethodAccessorImpl.invoke0(Native Method)
	at sun.reflect.NativeMethodAccessorImpl.invoke(Unknown Source)
	at sun.reflect.DelegatingMethodAccessorImpl.invoke(Unknown Source)
	at java.lang.reflect.Method.invoke(Unknown Source)
	at org.testng.internal.MethodInvocationHelper.invokeMethod(MethodInvocationHelper.java:104)
	at org.testng.internal.InvokeMethodRunnable.runOne(InvokeMethodRunnable.java:54)
	at org.testng.internal.InvokeMethodRunnable.run(InvokeMethodRunnable.java:44)
	at java.util.concurrent.Executors$RunnableAdapter.call(Unknown Source)
	at java.util.concurrent.FutureTask.run(Unknown Source)
	at java.util.concurrent.ThreadPoolExecutor.runWorker(Unknown Source)
	at java.util.concurrent.ThreadPoolExecutor$Worker.run(Unknown Source)
	at java.lang.Thread.run(Unknown Source)
]]>
    </failure>
  </testcase> <!-- verify -->
  <testcase name="verify" time="100.9" classname="com.adv.qa.selenium.tests.currency.A041_Group_Category_And_Structure_PostingsPostgreSQLTest">
    <failure type="java.lang.NullPointerException">
      <![CDATA[java.lang.NullPointerException
	at com.adv.qa.selenium.framework.Assert.assertEquals(Assert.java:156)
	at com.adv.qa.selenium.tests.currency.A041_Group_Category_And_Structure_PostingsPostgreSQLTest.processVerificationep4(A041_Group_Category_And_Structure_PostingsPostgreSQLTest.java:88)
	at com.adv.qa.selenium.tests.currency.A041_Group_Category_And_Structure_PostingsPostgreSQLTest.verify(A041_Group_Category_And_Structure_PostingsPostgreSQLTest.java:64)
	at sun.reflect.NativeMethodAccessorImpl.invoke0(Native Method)
	at sun.reflect.NativeMethodAccessorImpl.invoke(Unknown Source)
	at sun.reflect.DelegatingMethodAccessorImpl.invoke(Unknown Source)
	at java.lang.reflect.Method.invoke(Unknown Source)
	at org.testng.internal.MethodInvocationHelper.invokeMethod(MethodInvocationHelper.java:104)
	at org.testng.internal.InvokeMethodRunnable.runOne(InvokeMethodRunnable.java:54)
	at org.testng.internal.InvokeMethodRunnable.run(InvokeMethodRunnable.java:44)
	at java.util.concurrent.Executors$RunnableAdapter.call(Unknown Source)
	at java.util.concurrent.FutureTask.run(Unknown Source)
	at java.util.concurrent.ThreadPoolExecutor.runWorker(Unknown Source)
	at java.util.concurrent.ThreadPoolExecutor$Worker.run(Unknown Source)
	at java.lang.Thread.run(Unknown Source)
]]>
    </failure>
  </testcase> <!-- verify -->
</testsuite> <!-- suite20 -->
